{\rtf1\ansi\ansicpg1252\deff0\nouicompat\deflang1033{\fonttbl{\f0\fnil\fcharset0 Calibri;}}
{\colortbl ;\red0\green0\blue255;}
{\*\generator Riched20 6.3.9600}\viewkind4\uc1 
\pard\sa200\sl276\slmult1\f0\fs22\lang9 User.objects.create(first_name="who",last_name="dat",email="righthere@gmail.com",age="35",desc="unknown",)\par
User.objects.order_by("first_name")\par
\par
  File "C:\\Users\\kkps\\Desktop\\CDojo\\myEnviro\\djangoenv\\lib\\site-packages\\django\\\par
apps\\config.py", line 202, in import_models\par
    self.models_module = import_module(models_module_name)\par
  File "C:\\Users\\kkps\\AppData\\Local\\Enthought\\Canopy\\App\\appdata\\canopy-1.5.5.31\par
23.win-x86_64\\Lib\\importlib\\__init__.py", line 37, in import_module\par
    __import__(name)\par
  File "C:\\Users\\kkps\\Desktop\\CDojo\\pyStack\\Django\\users\\apps\\user_login\\models.\par
py", line 9, in <module>\par
    class User(models.Model):\par
  File "C:\\Users\\kkps\\Desktop\\CDojo\\pyStack\\Django\\users\\apps\\user_login\\models.\par
py", line 13, in User\par
    age = models.integer()\par
AttributeError: 'module' object has no attribute 'integer'\par
Unhandled exception in thread started by <function wrapper at 0x000000000328AEB8\par
>\par
Traceback (most recent call last):\par
  File "C:\\Users\\kkps\\Desktop\\CDojo\\myEnviro\\djangoenv\\lib\\site-packages\\django\\\par
utils\\autoreload.py", line 228, in wrapper\par
    fn(*args, **kwargs)\par
  File "C:\\Users\\kkps\\Desktop\\CDojo\\myEnviro\\djangoenv\\lib\\site-packages\\django\\\par
core\\management\\commands\\runserver.py", line 117, in inner_run\par
    autoreload.raise_last_exception()\par
  File "C:\\Users\\kkps\\Desktop\\CDojo\\myEnviro\\djangoenv\\lib\\site-packages\\django\\\par
utils\\autoreload.py", line 251, in raise_last_exception\par
    six.reraise(*_exception)\par
  File "C:\\Users\\kkps\\Desktop\\CDojo\\myEnviro\\djangoenv\\lib\\site-packages\\django\\\par
utils\\autoreload.py", line 228, in wrapper\par
    fn(*args, **kwargs)\par
  File "C:\\Users\\kkps\\Desktop\\CDojo\\myEnviro\\djangoenv\\lib\\site-packages\\django\\\par
__init__.py", line 27, in setup\par
    apps.populate(settings.INSTALLED_APPS)\par
  File "C:\\Users\\kkps\\Desktop\\CDojo\\myEnviro\\djangoenv\\lib\\site-packages\\django\\\par
apps\\registry.py", line 108, in populate\par
    app_config.import_models()\par
  File "C:\\Users\\kkps\\Desktop\\CDojo\\myEnviro\\djangoenv\\lib\\site-packages\\django\\\par
apps\\config.py", line 202, in import_models\par
    self.models_module = import_module(models_module_name)\par
  File "C:\\Users\\kkps\\AppData\\Local\\Enthought\\Canopy\\App\\appdata\\canopy-1.5.5.31\par
23.win-x86_64\\Lib\\importlib\\__init__.py", line 37, in import_module\par
    __import__(name)\par
  File "C:\\Users\\kkps\\Desktop\\CDojo\\pyStack\\Django\\users\\apps\\user_login\\models.\par
py", line 9, in <module>\par
    class User(models.Model):\par
  File "C:\\Users\\kkps\\Desktop\\CDojo\\pyStack\\Django\\users\\apps\\user_login\\models.\par
py", line 13, in User\par
    age = models.integerField()\par
AttributeError: 'module' object has no attribute 'integerField'\par
Performing system checks...\par
\par
System check identified no issues (0 silenced).\par
\par
You have 13 unapplied migration(s). Your project may not work properly until you\par
 apply the migrations for app(s): admin, auth, contenttypes, sessions.\par
Run 'python manage.py migrate' to apply them.\par
October 16, 2017 - 15:50:55\par
Django version 1.11.6, using settings 'users.settings'\par
Starting development server at {{\field{\*\fldinst{HYPERLINK http://127.0.0.1:8000/ }}{\fldrslt{http://127.0.0.1:8000/\ul0\cf0}}}}\f0\fs22\par
Quit the server with CTRL-BREAK.\par
Performing system checks...\par
\par
System check identified no issues (0 silenced).\par
\par
You have 13 unapplied migration(s). Your project may not work properly until you\par
 apply the migrations for app(s): admin, auth, contenttypes, sessions.\par
Run 'python manage.py migrate' to apply them.\par
October 16, 2017 - 15:52:28\par
Django version 1.11.6, using settings 'users.settings'\par
Starting development server at {{\field{\*\fldinst{HYPERLINK http://127.0.0.1:8000/ }}{\fldrslt{http://127.0.0.1:8000/\ul0\cf0}}}}\f0\fs22\par
Quit the server with CTRL-BREAK.\par
Unhandled exception in thread started by <function wrapper at 0x000000000337AEB8\par
>\par
Traceback (most recent call last):\par
  File "C:\\Users\\kkps\\Desktop\\CDojo\\myEnviro\\djangoenv\\lib\\site-packages\\django\\\par
utils\\autoreload.py", line 228, in wrapper\par
    fn(*args, **kwargs)\par
  File "C:\\Users\\kkps\\Desktop\\CDojo\\myEnviro\\djangoenv\\lib\\site-packages\\django\\\par
core\\management\\commands\\runserver.py", line 117, in inner_run\par
    autoreload.raise_last_exception()\par
  File "C:\\Users\\kkps\\Desktop\\CDojo\\myEnviro\\djangoenv\\lib\\site-packages\\django\\\par
utils\\autoreload.py", line 251, in raise_last_exception\par
    six.reraise(*_exception)\par
  File "C:\\Users\\kkps\\Desktop\\CDojo\\myEnviro\\djangoenv\\lib\\site-packages\\django\\\par
utils\\autoreload.py", line 228, in wrapper\par
    fn(*args, **kwargs)\par
  File "C:\\Users\\kkps\\Desktop\\CDojo\\myEnviro\\djangoenv\\lib\\site-packages\\django\\\par
__init__.py", line 27, in setup\par
    apps.populate(settings.INSTALLED_APPS)\par
  File "C:\\Users\\kkps\\Desktop\\CDojo\\myEnviro\\djangoenv\\lib\\site-packages\\django\\\par
apps\\registry.py", line 108, in populate\par
    app_config.import_models()\par
  File "C:\\Users\\kkps\\Desktop\\CDojo\\myEnviro\\djangoenv\\lib\\site-packages\\django\\\par
apps\\config.py", line 202, in import_models\par
    self.models_module = import_module(models_module_name)\par
  File "C:\\Users\\kkps\\AppData\\Local\\Enthought\\Canopy\\App\\appdata\\canopy-1.5.5.31\par
23.win-x86_64\\Lib\\importlib\\__init__.py", line 37, in import_module\par
    __import__(name)\par
  File "C:\\Users\\kkps\\Desktop\\CDojo\\pyStack\\Django\\users\\apps\\user_login\\models.\par
py", line 9, in <module>\par
    class User(models.Model):\par
  File "C:\\Users\\kkps\\Desktop\\CDojo\\pyStack\\Django\\users\\apps\\user_login\\models.\par
py", line 13, in User\par
    age = models.IntegerField(max=70)\par
TypeError: __init__() got an unexpected keyword argument 'max'\par
Performing system checks...\par
\par
System check identified no issues (0 silenced).\par
\par
You have 13 unapplied migration(s). Your project may not work properly until you\par
 apply the migrations for app(s): admin, auth, contenttypes, sessions.\par
Run 'python manage.py migrate' to apply them.\par
October 16, 2017 - 15:52:48\par
Django version 1.11.6, using settings 'users.settings'\par
Starting development server at {{\field{\*\fldinst{HYPERLINK http://127.0.0.1:8000/ }}{\fldrslt{http://127.0.0.1:8000/\ul0\cf0}}}}\f0\fs22\par
Quit the server with CTRL-BREAK.\par
Unhandled exception in thread started by <function wrapper at 0x0000000003288128\par
>\par
Traceback (most recent call last):\par
  File "C:\\Users\\kkps\\Desktop\\CDojo\\myEnviro\\djangoenv\\lib\\site-packages\\django\\\par
utils\\autoreload.py", line 228, in wrapper\par
    fn(*args, **kwargs)\par
  File "C:\\Users\\kkps\\Desktop\\CDojo\\myEnviro\\djangoenv\\lib\\site-packages\\django\\\par
core\\management\\commands\\runserver.py", line 117, in inner_run\par
    autoreload.raise_last_exception()\par
  File "C:\\Users\\kkps\\Desktop\\CDojo\\myEnviro\\djangoenv\\lib\\site-packages\\django\\\par
utils\\autoreload.py", line 251, in raise_last_exception\par
    six.reraise(*_exception)\par
  File "C:\\Users\\kkps\\Desktop\\CDojo\\myEnviro\\djangoenv\\lib\\site-packages\\django\\\par
utils\\autoreload.py", line 228, in wrapper\par
    fn(*args, **kwargs)\par
  File "C:\\Users\\kkps\\Desktop\\CDojo\\myEnviro\\djangoenv\\lib\\site-packages\\django\\\par
__init__.py", line 27, in setup\par
    apps.populate(settings.INSTALLED_APPS)\par
  File "C:\\Users\\kkps\\Desktop\\CDojo\\myEnviro\\djangoenv\\lib\\site-packages\\django\\\par
apps\\registry.py", line 108, in populate\par
    app_config.import_models()\par
  File "C:\\Users\\kkps\\Desktop\\CDojo\\myEnviro\\djangoenv\\lib\\site-packages\\django\\\par
apps\\config.py", line 202, in import_models\par
    self.models_module = import_module(models_module_name)\par
  File "C:\\Users\\kkps\\AppData\\Local\\Enthought\\Canopy\\App\\appdata\\canopy-1.5.5.31\par
23.win-x86_64\\Lib\\importlib\\__init__.py", line 37, in import_module\par
    __import__(name)\par
  File "C:\\Users\\kkps\\Desktop\\CDojo\\pyStack\\Django\\users\\apps\\user_login\\models.\par
py", line 13\par
    age = models.IntegerField(default=NOT_PROVIDED=70)\par
                                                  ^\par
SyntaxError: invalid syntax\par
Performing system checks...\par
\par
System check identified no issues (0 silenced).\par
\par
You have 13 unapplied migration(s). Your project may not work properly until you\par
 apply the migrations for app(s): admin, auth, contenttypes, sessions.\par
Run 'python manage.py migrate' to apply them.\par
October 16, 2017 - 15:52:56\par
Django version 1.11.6, using settings 'users.settings'\par
Starting development server at {{\field{\*\fldinst{HYPERLINK http://127.0.0.1:8000/ }}{\fldrslt{http://127.0.0.1:8000/\ul0\cf0}}}}\f0\fs22\par
Quit the server with CTRL-BREAK.\par
\par
(djangoenv) C:\\Users\\kkps\\Desktop\\CDojo\\pyStack\\Django\\users>python manage.py ma\par
kemigrations\par
Migrations for 'user_login':\par
  apps\\user_login\\migrations\\0001_initial.py\par
    - Create model User\par
\par
(djangoenv) C:\\Users\\kkps\\Desktop\\CDojo\\pyStack\\Django\\users>python manage.py mi\par
grate\par
Operations to perform:\par
  Apply all migrations: admin, auth, contenttypes, sessions, user_login\par
Running migrations:\par
  Applying contenttypes.0001_initial... OK\par
  Applying auth.0001_initial... OK\par
  Applying admin.0001_initial... OK\par
  Applying admin.0002_logentry_remove_auto_add... OK\par
  Applying contenttypes.0002_remove_content_type_name... OK\par
  Applying auth.0002_alter_permission_name_max_length... OK\par
  Applying auth.0003_alter_user_email_max_length... OK\par
  Applying auth.0004_alter_user_username_opts... OK\par
  Applying auth.0005_alter_user_last_login_null... OK\par
  Applying auth.0006_require_contenttypes_0002... OK\par
  Applying auth.0007_alter_validators_add_error_messages... OK\par
  Applying auth.0008_alter_user_username_max_length... OK\par
  Applying sessions.0001_initial... OK\par
  Applying user_login.0001_initial... OK\par
\par
(djangoenv) C:\\Users\\kkps\\Desktop\\CDojo\\pyStack\\Django\\users>users_login.objects\par
.all()\par
'users_login.objects.all' is not recognized as an internal or external command,\par
operable program or batch file.\par
\par
(djangoenv) C:\\Users\\kkps\\Desktop\\CDojo\\pyStack\\Django\\users>user.objects.all()\par
'user.objects.all' is not recognized as an internal or external command,\par
operable program or batch file.\par
\par
(djangoenv) C:\\Users\\kkps\\Desktop\\CDojo\\pyStack\\Django\\users>user.object.create(\par
first_name="toll",last_name="free",email="tollfree@gmail.com",age="29",desc="rou\par
ghedges")\par
'user.object.create' is not recognized as an internal or external command,\par
operable program or batch file.\par
\par
(djangoenv) C:\\Users\\kkps\\Desktop\\CDojo\\pyStack\\Django\\users>python manage.py sh\par
ell\par
Python 2.7.9 |CUSTOM| (default, Jul  1 2015, 03:41:50) [MSC v.1500 64 bit (AMD64\par
)] on win32\par
Type "help", "copyright", "credits" or "license" for more information.\par
(InteractiveConsole)\par
>>> from apps.user_login.models import *\par
>>> user.object.create(\par
... first_name="toll",last_name="free",email="tollfree@gmail.com",age="29",desc=\par
"rou\par
  File "<console>", line 2\par
    first_name="toll",last_name="free",email="tollfree@gmail.com",age="29",desc=\par
"rou\par
\par
   ^\par
SyntaxError: EOL while scanning string literal\par
>>> user.object.create(\par
... first_name="toll",last_name="free",email="tollfree@gmail.com",age="29",desc=\par
"roughedges")\par
Traceback (most recent call last):\par
  File "<console>", line 1, in <module>\par
NameError: name 'user' is not defined\par
>>> user.object.create(\par
...\par
...\par
...\par
... user.object.create(\par
... first_name="toll",last_name="free",email="tollfree@gmail.com",age="29",desc=\par
"roughedges")\par
... user.object.create(\par
  File "<console>", line 7\par
    user.object.create(\par
       ^\par
SyntaxError: invalid syntax\par
>>> first_name="toll",last_name="free",email="tollfree@gmail.com",age="29",desc=\par
"roughedges")\par
  File "<console>", line 1\par
    first_name="toll",last_name="free",email="tollfree@gmail.com",age="29",desc=\par
"roughedges")\par
\par
            ^\par
SyntaxError: invalid syntax\par
>>> user.object.create(\par
... first_name="toll",last_name="free",email="tollfree@gmail.com",age="29",desc=\par
"roughedges",)\par
Traceback (most recent call last):\par
  File "<console>", line 1, in <module>\par
NameError: name 'user' is not defined\par
>>> User.object.create(first_name="toll",last_name="free",email="tollfree@gmail.\par
com",age="29",desc="roughedges",)\par
Traceback (most recent call last):\par
  File "<console>", line 1, in <module>\par
AttributeError: type object 'User' has no attribute 'object'\par
>>> User.objects.create(first_name="toll",last_name="free",email="tollfree@gmail\par
.com",age="29",desc="roughedges",)\par
<User: User object>\par
>>> Users.objects.last()\par
Traceback (most recent call last):\par
  File "<console>", line 1, in <module>\par
NameError: name 'Users' is not defined\par
>>> User.objects.last()\par
<User: User object>\par
>>> User.object.create(first_name="mike",last_name="bulls",email="mvp@gmail.com"\par
,age="39",desc="champ",)\par
Traceback (most recent call last):\par
  File "<console>", line 1, in <module>\par
AttributeError: type object 'User' has no attribute 'object'\par
>>> User.objects.create(first_name="mike",last_name="bulls",email="mvp@gmail.com\par
",age="39",desc="champ",)\par
<User: User object>\par
>>> User.objects.create(first_name="who",last_name="dat",email="righthere@gmail.\par
com",age="35",desc="unknown",)\par
<User: User object>\par
>>> User.objects.first()\par
<User: User object>\par
>>> User.objects.order_by(first_name DESC)\par
  File "<console>", line 1\par
    User.objects.order_by(first_name DESC)\par
                                        ^\par
SyntaxError: invalid syntax\par
>>> User.objects.order_by("first_name")\par
<QuerySet [<User: User object>, <User: User object>, <User: User object>]>\par
>>> User.objects.get(id=1)\par
<User: User object>\par
>>> b=User.objects.get(id=1)\par
>>> b.first_name="chicagoskyline"\par
>>> b.save()\par
>>> b=User.objects.get(id=4)\par
Traceback (most recent call last):\par
  File "<console>", line 1, in <module>\par
  File "C:\\Users\\kkps\\Desktop\\CDojo\\myEnviro\\djangoenv\\lib\\site-packages\\django\\\par
db\\models\\manager.py", line 85, in manager_method\par
    return getattr(self.get_queryset(), name)(*args, **kwargs)\par
  File "C:\\Users\\kkps\\Desktop\\CDojo\\myEnviro\\djangoenv\\lib\\site-packages\\django\\\par
db\\models\\query.py", line 380, in get\par
    self.model._meta.object_name\par
DoesNotExist: User matching query does not exist.\par
>>> b=User.objects.get(id=3)\par
>>> b.delete()\par
(1, \{u'user_login.User': 1\})\par
>>>\par
\par
}
 